Workbook

Sheet КП с ндс
C2: ООО НПО "Энергон"
C3: ИНН: 3663147250
C4: ОГРН: 1203600002760
C5: КПП: 366301001
B7: № Дата:
A9: Уважаемые Господа!
A11: ООО НПО"Энергон" предлагает Вашему вниманию коммерческое предложение, согласно спецификации.
A13: Спецификация:
A14: № | B14: Товары(работы, услуги) | C14: кол-во | D14: Цена за единицу с НДС (руб.) | E14: Сумма с НДС (руб.)
A15: 1 | B15: =Расчёт!C3 | C15: 10 | D15: =Расчёт!L8 | E15: =D15*C15
B16: =Расчёт!C12
B17: =Расчёт!C21
B18: =Расчёт!C30
B19: =Расчёт!C39
B20: =Расчёт!C48
B21: =Расчёт!C57
B22: =Расчёт!C66
B23: =Расчёт!C75
B24: =Расчёт!C84
A26: Итого без НДС: | E26: =E28/1.22
D27: в том числе НДС 22%: | E27: =E28-E26
A28: Итого с НДС: | E28: =SUM(E15:E24)
A29: Срок действия предложения - 3 рабочих дня.
A30: Условия оплаты: обсуждаются при заказе.
A31: Срок выполнения заказа -
A33: С уважением,
A34: Пермяков Сергей Сергеевич
A35: E-mail: pss@npo-energon.ru
A36: Тел.: 8-960-133-74-57

Sheet Расчёт
A1: 1
A2: Наименование | B2: Примечание | C2: Материал | D2: Цена за лист/кг. для порошковой покраски | E2: Листов/ м.кв. для порошковой покраски | F2: Стоимость материалов | G2: Стоимость часа | H2: Часов | I2: Стоимость работ | J2: Прибыль с часа/м2 | K2: Прибыль с работ | L2: Итого | N2: Работы и материал | P2: Время работы, ч | Q2: Себест., РУБ | R2: Прибыль, РУБ | S2: Всего
A3: Тестовая деталь | C3: 2,0 мм Ст3 (2500х1250) | D3: =VLOOKUP(C3,'Цены на металл'!$A$3:$H$30,7,0) | E3: 1 | F3: =D3*E3 | G3: 4800 | H3: 0.5 | I3: =H3*G3 | K3: =H3*J3 | L3: =F3+I3+K3 | N3: Работа | O3: Лазерная резка | P3: =SUM(H3,H12,H21,H30,H39,H48,H57,H66,H75,H84) | Q3: =I3+I12+I21+I30+I39+I48+I57+I66+I75+I84 | R3: =SUM(K3,K12,K21,K30,K39,K48,K57,K66,K75,K84) | S3: =SUM(Q3:R7)
A4: Гибка (84 гибов в час) | F4: =D4*E4 | G4: 2685 | H4: 0.2 | I4: =H4*G4 | K4: =H4*J4 | L4: =F4+I4+K4 | O4: Гибка | P4: =SUM(H4,H13,H22,H31,H40,H49,H58,H67,H76,H85) | Q4: =SUM(I4,I13,I22,I31,I40,I49,I58,I67,I76,I85) | R4: =SUM(K4,K13,K22,K31,K40,K49,K58,K67,K76,K85)
A5: Токарка | F5: 0 | G5: 4800 | I5: =H5*G5 | K5: =H5*J5 | L5: =F5+I5+K5 | O5: Порошковая покраска | P5: =SUM(H7,H16,H25,H34,H43,H52,H61,H70,H79,H88) | Q5: =SUM(I7,I16,I25,I34,I43,I52,I61,I70,I79,I88) | R5: =SUM(K7,K16,K25,K34,K43,K52,K61,K70,K79,K88)
A6: Сварка | F6: =D6*E6 | G6: 1980 | I6: =H6*G6 | K6: =H6*J6 | L6: =F6+I6+K6 | O6: Сварка | P6: =SUM(H6,H15,H24,H33,H42,H51,H69,H78,H87) | Q6: =SUM(I6,I15,I24,I33,I42,I51,I60,I69,I78,I87) | R6: =SUM(K6,K15,K24,K33,K42,K51,K60,K69,K78,K87)
A7: Порошковая покраска 5,53 кв. м/час. | B7: Порошковая покраска | D7: =VLOOKUP(B7,'Цены на металл'!$A$36:$B$39,2,0) | F7: =E7*0.3*D7 | G7: 2500 | I7: =H7*G7 | K7: =J7*H7 | L7: =F7+I7+K7 | O7: Токарка | P7: =SUM(H5,H14,H23,H32,H41,H50,H59,H77,H86,H68) | Q7: =SUM(I5,I14,I23,I32,I41,I59,I68,I77,I86) | R7: =SUM(K5,K14,K23,K32,K41,K50,K59,K68,K77,K86)
K8: =SUM(K3:K7) | L8: =SUM(L3:L7) | N8: Материал | O8: Металл: | Q8: =SUM(F3,F12,F21,F30,F39,F48,F57,F66,F75,F84) | S8: =SUM(Q8:Q10)
O9: Краска порошок | Q9: =SUM(F7,F16,F25,F34,F43,F52,F61,F70,F79,F88)
A10: 2 | O10: Покупные изделия | T10: Проверка
A11: Наименование | B11: Примечание | C11: Материал | D11: Цена за лист/кг. для порошковой покраски | E11: Листов/ м.кв. для порошковой покраски | F11: Стоимость материалов | G11: Стоимость часа | H11: Часов | I11: Стоимость работ | J11: Прибыль с часа/м2 | K11: Прибыль с работ | L11: Итого | N11: Итого | P11: =SUM(P3:P7) | Q11: =SUM(Q3:Q10) | R11: =SUM(R3:R10) | S11: =SUM(S3:S10) | T11: =L8+L17+L26+L35+L44+L53+L62+L71+L80+L89
A12: Изделие 2 | D12: =VLOOKUP(C12,'Цены на металл'!$A$3:$H$30,7,0) | F12: =D12*E12 | G12: 4800 | I12: =H12*G12 | K12: =H12*J12 | L12: =F12+I12+K12
A13: Гибка (84 гибов в час) | F13: =D13*E13 | G13: 2685 | I13: =H13*G13 | K13: =H13*J13 | L13: =F13+I13+K13
A14: Токарка | F14: 0 | G14: 4800 | I14: =G14*H14 | K14: =H14*J14 | L14: =F14+I14+K14
A15: Сварка | F15: =D15*E15 | G15: 1980 | I15: =H15*G15 | K15: =H15*J15 | L15: =F15+I15+K15
A16: Порошковая покраска 5,53 кв. м/час. | B16: Порошковая покраска | D16: =VLOOKUP(B16,'Цены на металл'!$A$36:$B$39,2,0) | F16: =E16*0.3*D16 | G16: 2500 | I16: =H16*G16 | K16: =J16*H16 | L16: =F16+I16+K16 | N16: Металл | P16: Покраска | R16: Другое
K17: =SUM(K12:K16) | L17: =SUM(L12:L16) | N17: Марка стали | O17: Листов/ м.кв. для порошковой покраски | P17: Материал покраски/RAL | Q17: Использовано, кг. | R17: Материал | S17: Использовано
N18: =C3 | O18: =E3 | P18: =C7 | Q18: =E7*0.3
A19: 3 | N19: =C12 | O19: =E12 | P19: =C16 | Q19: =E16*0.3
A20: Наименование | B20: Примечание | C20: Материал | D20: Цена за лист/кг. для порошковой покраски | E20: Листов/ м.кв. для порошковой покраски | F20: Стоимость материалов | G20: Стоимость часа | H20: Часов | I20: Стоимость работ | J20: Прибыль с часа/м2 | K20: Прибыль с работ | L20: Итого | N20: =C21 | O20: =E21 | P20: =C25 | Q20: =E25*0.3
A21: Изделие 3 | D21: =VLOOKUP(C21,'Цены на металл'!$A$3:$H$30,7,0) | F21: =D21*E21 | G21: 4800 | I21: =H21*G21 | K21: =H21*J21 | L21: =F21+I21+K21 | N21: =C30 | O21: =E30 | P21: =C34 | Q21: =E34*0.3
A22: Гибка (84 гибов в час) | F22: =D22*E22 | G22: 2685 | I22: =H22*G22 | K22: =H22*J22 | L22: =F22+I22+K22 | N22: =C39 | O22: =E39 | P22: =C43 | Q22: =E43*0.3
A23: Токарка | F23: 0 | G23: 4800 | I23: =G23*H23 | K23: =H23*J23 | L23: =F23+I23+K23 | N23: =C48 | O23: =E48 | P23: =C52 | Q23: =E52*0.3
A24: Сварка | F24: =D24*E24 | G24: 1980 | I24: =H24*G24 | K24: =H24*J24 | L24: =F24+I24+K24 | N24: =C57 | O24: =E57 | P24: =C61 | Q24: =E61*0.3
A25: Порошковая покраска 5,53 кв. м/час. | B25: Порошковая покраска | D25: =VLOOKUP(B25,'Цены на металл'!$A$36:$B$39,2,0) | F25: =E25*0.3*D25 | G25: 2500 | I25: =H25*G25 | K25: =J25*H25 | L25: =F25+I25+K25 | N25: =C66 | O25: =E66 | P25: =C70 | Q25: =E70*0.3
K26: =SUM(K21:K25) | L26: =SUM(L21:L25) | N26: =C75 | O26: =E75 | P26: =C79 | Q26: =E79*0.3
N27: =C84 | O27: =E84 | P27: =C88 | Q27: =E88*0.3
A28: 4
A29: Наименование | B29: Примечание | C29: Материал | D29: Цена за лист/кг. для порошковой покраски | E29: Листов/ м.кв. для порошковой покраски | F29: Стоимость материалов | G29: Стоимость часа | H29: Часов | I29: Стоимость работ | J29: Прибыль с часа/м2 | K29: Прибыль с работ | L29: Итого
A30: Изделие 4 | D30: =VLOOKUP(C30,'Цены на металл'!$A$3:$H$30,7,0) | F30: =D30*E30 | G30: 4800 | I30: =H30*G30 | K30: =H30*J30 | L30: =F30+I30+K30
A31: Гибка (84 гибов в час) | F31: =D31*E31 | G31: 2685 | I31: =H31*G31 | K31: =H31*J31 | L31: =F31+I31+K31
A32: Токарка | F32: 0 | G32: 4800 | I32: =G32*H32 | K32: =H32*J32 | L32: =F32+I32+K32
A33: Сварка | F33: =D33*E33 | G33: 1980 | I33: =H33*G33 | K33: =H33*J33 | L33: =F33+I33+K33
A34: Порошковая покраска 5,53 кв. м/час. | B34: Порошковая покраска | D34: =VLOOKUP(B34,'Цены на металл'!$A$36:$B$39,2,0) | F34: =E34*0.3*D34 | G34: 2500 | I34: =H34*G34 | K34: =J34*H34 | L34: =F34+I34+K34
K35: =SUM(K30:K34) | L35: =SUM(L30:L34)
A37: 5
A38: Наименование | B38: Примечание | C38: Материал | D38: Цена за лист/кг. для порошковой покраски | E38: Листов/ м.кв. для порошковой покраски | F38: Стоимость материалов | G38: Стоимость часа | H38: Часов | I38: Стоимость работ | J38: Прибыль с часа/м2 | K38: Прибыль с работ | L38: Итого
A39: Изделие 5 | D39: =VLOOKUP(C39,'Цены на металл'!$A$3:$H$30,7,0) | F39: =D39*E39 | G39: 4800 | I39: =H39*G39 | K39: =H39*J39 | L39: =F39+I39+K39
A40: Гибка (84 гибов в час) | F40: =D40*E40 | G40: 2685 | I40: =H40*G40 | K40: =H40*J40 | L40: =F40+I40+K40
A41: Токарка | F41: 0 | G41: 4800 | I41: =G41*H41 | K41: =H41*J41 | L41: =F41+I41+K41
...

Sheet Цены на металл
A2: Наименование | B2: Цена за тонну, р. | C2: Площадь листа, м2 | D2: Вес 1м2, т | E2: Вес одного листа, т | F2: Резка листа под размер лазера, р. | G2: Итого за 1 лист, р. | H2: Стоимость 1м2, р | I2: Последние закупочные цены | J2: Расчетная себестоимость 1 метра прямого реза | K2: Цена на последние числа декабря. | L2: 46239 | O2: 46252 | AB2: конец марта
A3: - | L3: окама | M3: Сталепром. | O3: Сталепром. | AB3: Металлинвест
A4: 0,5 мм Оц. Сталь (2500х1250) | B4: 98880 | C4: 3.125 | D4: 0.004025 | E4: =D4*C4 | G4: =B4*E4+F4 | H4: =G4/C4 | I4: 106000 | K4: 107800 | O4: 96000 | P4: =O4*1.03
A5: 1,0 мм Оц. Сталь (2500х1250) | B5: 97000 | C5: 3.125 | D5: =E5/C5 | E5: 0.0245 | G5: =B5*E5+F5 | H5: =G5/C5 | I5: 96000 | L5: 94900 | O5: 92500 | P5: =O5*1.03 | S5: 46092 | AA5: 102000 | AB5: 96840 | AC5: =AB5*1.03 | AD5: =AB5*1.05
A6: 1,2 мм Оц. Сталь (2500х1250) | B6: 97000 | C6: 3.125 | D6: =E6/C6 | E6: 0.03 | G6: =B6*E6+F6 | H6: =G6/C6 | I6: 96000 | O6: 90500 | P6: =O6*1.03 | S6: Март | T6: Фераль | AB6: 96500 | AC6: =AB6*1.03 | AD6: =AB6*1.05
A7: 1,5 мм Оц. Сталь (2500х1250) | B7: 97000 | C7: 3.125 | D7: =E7/C7 | E7: 0.0368 | G7: =B7*E7+F7 | H7: =G7/C7 | I7: 96000 | O7: 90500 | P7: =O7*1.03 | S7: Сталепром | T7: Окама | U7: металинвест | V7: Окама | W7: Окама | X7: Среднее | AB7: 96500 | AC7: =AB7*1.03 | AD7: =AB7*1.05
A8: 2,0 мм Оц. Сталь (2500х1250) | B8: 97000 | C8: 3.125 | D8: =E8/C8 | E8: 0.0491 | G8: =B8*E8+F8 | H8: =G8/C8 | I8: 96000 | K8: 97300 | L8: 92500 | N8: 89000 | O8: 89000 | P8: =O8*1.03 | Q8: =L8*1.03 | S8: 91600 | T8: 98712.64 | U8: 97900 | W8: =79210*1.22 | X8: =AVERAGE(T8:W8) | Y8: =X8/B8-1 | Z8: =S8/T8-1 | AB8: 95500 | AC8: =AB8*1.03 | AD8: =AB8*1.05
A9: 3,0 мм Оц. Сталь (2500х1250) | B9: 97000 | C9: 3.125 | D9: =E9/C9 | E9: 0.0736 | G9: =B9*E9+F9 | H9: =G9/C9 | I9: 96000 | N9: 88000 | O9: 88000 | P9: =O9*1.03 | AB9: 95500 | AC9: =AB9*1.03 | AD9: =AB9*1.05
A10: 0,7 мм Х.к. Сталь (2500х1250) | B10: 80000 | C10: 3.125 | D10: =E10/C10 | E10: 0.0175 | G10: =B10*E10+F10 | H10: =G10/C10 | I10: 81996 | O10: 69700 | P10: =O10*1.03 | AB10: 77500 | AC10: =AB10*1.03 | AD10: =AB10*1.05
A11: 1,0 мм Х.к. Сталь (2500х1250) | B11: 80000 | C11: 3.125 | D11: =E11/C11 | E11: 0.0245 | G11: =B11*E11+F11 | H11: =G11/C11 | I11: 81996 | M11: 70500 | O11: 69700 | P11: =O11*1.03 | S11: 74000 | T11: 83712.74 | U11: 78898 | V11: =68396*1.22 | W11: =67735*1.22 | X11: =AVERAGE(T11:W11) | Y11: =X11/B11-1 | Z11: =S11/T11-1 | AB11: 77500 | AC11: =AB11*1.03 | AD11: =AB11*1.05
A12: 1,2 мм Х.к. Сталь (2500х1250) | B12: 80000 | C12: 3.125 | D12: =E12/C12 | E12: 0.03 | G12: =B12*E12+F12 | H12: =G12/C12 | I12: 81996 | O12: 69700 | P12: =O12*1.03 | S12: 74000 | T12: 83712.74 | U12: 78899 | V12: =68396*1.22 | W12: =67735*1.22 | X12: =AVERAGE(T12:W12) | Y12: =X12/B12-1 | Z12: =S12/T12-1 | AB12: 77500 | AC12: =AB12*1.03 | AD12: =AB12*1.05
A13: 1,5 мм Х.к. Сталь (2500х1250) | B13: 80000 | C13: 3.125 | D13: =E13/C13 | E13: 0.0368 | G13: =B13*E13+F13 | H13: =G13/C13 | I13: 81996 | K13: 83300 | L13: 78000 | O13: 69700 | P13: =O13*1.03 | S13: 74000 | T13: 83712.74 | U13: 78900 | V13: =68396*1.22 | W13: =67735*1.22 | X13: =AVERAGE(T13:W13) | Y13: % | Z13: =S13/T13-1 | AA13: 82500 | AB13: 77500 | AC13: =AB13*1.03 | AD13: =AB13*1.05
A14: 2,0 мм Х.к. Сталь (2500х1250) | B14: 80000 | C14: 3.125 | D14: =E14/C14 | E14: 0.0491 | G14: =B14*E14+F14 | H14: =G14/C14 | I14: 81996 | K14: 82720 | L14: 78000 | N14: 75180 | O14: 69700 | P14: =O14*1.03 | S14: 73800 | T14: 83712.74 | U14: 78900 | V14: =68396*1.22 | W14: =67735*1.22 | X14: =AVERAGE(T14:W14) | Y14: =X14/B14-1 | Z14: =S14/T14-1 | AA14: 82500 | AB14: 77500 | AC14: =AB14*1.03 | AD14: =AB14*1.05
A15: 3,0 мм Х.к. Сталь (2500х1250) | B15: 80000 | C15: 3.125 | D15: =E15/C15 | E15: 0.0736 | G15: =B15*E15+F15 | H15: =G15/C15 | I15: 81996 | O15: 69700 | P15: =O15*1.03 | R15: =M15*1.03 | AB15: 77500 | AC15: =AB15*1.03 | AD15: =AB15*1.05
A16: 1,0 мм Ст3 (2500х1250) | B16: 0 | C16: 3.125 | D16: =E16/C16 | E16: 0.0245 | G16: =B16*E16+F16 | H16: =G16/C16 | I16: 61000 | J16: 11 | P16: =O16*1.03 | R16: =M16*1.03 | AB16: 61000 | AC16: =AB16*1.03 | AD16: =AB16*1.05
A17: 1,5 мм Ст3 (2500х1250) | B17: 0 | C17: 3.125 | D17: =E17/C17 | E17: 0.0368 | G17: =B17*E17+F17 | H17: =G17/C17 | I17: 61000 | J17: 16 | P17: =O17*1.03 | R17: =M17*1.03 | AB17: 61000 | AC17: =AB17*1.03 | AD17: =AB17*1.05
A18: 2,0 мм Ст3 (2500х1250) | B18: 0 | C18: 3.125 | D18: =E18/C18 | E18: 0.0491 | G18: =B18*E18+F18 | H18: =G18/C18 | I18: 61000 | J18: 20.5 | P18: =O18*1.03 | R18: =M18*1.03 | AB18: 61000 | AC18: =AB18*1.03 | AD18: =AB18*1.05
A19: 3,0 мм Ст3 (3000х1500) | B19: 73000 | C19: 4.5 | D19: =E19/C19 | E19: 0.108 | F19: 60 | G19: =B19*E19+F19 | H19: =G19/C19 | I19: 60500 | J19: 32 | M19: 67300 | O19: 66300 | P19: =O19*1.03 | R19: =M19*1.03 | S19: 57200 | T19: 62212.68 | U19: =49100*1.22 | V19: =50773*1.22 | W19: =50112*1.22 | X19: =AVERAGE(T19:W19) | Y19: =X19/B19-1 | Z19: =S19/T19-1 | AA19: 60000 | AB19: 59500 | AC19: =AB19*1.03 | AD19: =AB19*1.05
A20: 4,0 мм Ст3 (3000х1500) | B20: 73000 | C20: 4.5 | D20: =E20/C20 | E20: 0.1413 | F20: 120 | G20: =B20*E20+F20 | H20: =G20/C20 | I20: 60500 | J20: 43 | K20: 61220 | L20: 83500 | N20: 66900 | O20: 66300 | P20: =O20*1.03 | R20: =M20*1.03 | S20: 55300 | T20: 62212.68 | U20: =49100*1.22 | V20: =50773*1.22 | W20: =50112*1.22 | X20: =AVERAGE(T20:W20) | Y20: =X20/B20-1 | Z20: =S20/T20-1 | AA20: 60000 | AB20: 58300 | AC20: =AB20*1.03 | AD20: =AB20*1.05
A21: 5,0 мм Ст3 (3000х1500) | B21: 73000 | C21: 4.5 | D21: =E21/C21 | E21: 0.1766 | F21: 180 | G21: =B21*E21+F21 | H21: =G21/C21 | I21: 60500 | J21: 53.5 | K21: 61220 | L21: 72500 | N21: 67970 | O21: 66300 | P21: =O21*1.03 | R21: =M21*1.03 | S21: 55300 | T21: 62212.68 | U21: =49590*1.22 | V21: =50773*1.22 | W21: =50112*1.22 | X21: =AVERAGE(T21:W21) | Y21: =X21/B21-1 | Z21: =S21/T21-1 | AA21: 60000 | AB21: 58300 | AC21: =AB21*1.03 | AD21: =AB21*1.05
A22: 6,0 мм Ст3 (3000х1500) | B22: 73000 | C22: 4.5 | D22: =E22/C22 | E22: 0.212 | F22: 180 | G22: =B22*E22+F22 | H22: =G22/C22 | I22: 60500 | J22: 64 | K22: 61220 | L22: 72500 | O22: 66300 | P22: =O22*1.03 | R22: =M22*1.03 | S22: 55300 | T22: 62212.68 | U22: =49590*1.22 | V22: =50773*1.22 | W22: =50112*1.22 | X22: =AVERAGE(T22:W22) | Y22: =X22/B22-1 | Z22: =S22/T22-1 | AA22: 60000 | AB22: 58300 | AC22: =AB22*1.03 | AD22: =AB22*1.05
A23: 8,0 мм Ст3 (3000х1500) | B23: 73000 | C23: 4.5 | D23: =E23/C23 | E23: 0.2826 | F23: 240 | G23: =B23*E23+F23 | H23: =G23/C23 | I23: 60500 | J23: 85 | K23: 61220 | L23: 78500 | M23: 65300 | O23: 66300 | P23: =O23*1.03 | R23: =M23*1.03 | S23: 55300 | T23: 62212.68 | U23: =49590*1.22 | V23: =50773*1.22 | W23: =50112*1.22 | X23: =AVERAGE(T23:W23) | Y23: =X23/B23-1 | Z23: =S23/T23-1 | AA23: 60000 | AB23: 57800 | AC23: =AB23*1.03 | AD23: =AB23*1.05
A24: 10,0 мм Ст3 (3000х1500) | B24: 73000 | C24: 4.5 | D24: =E24/C24 | E24: 0.362 | F24: 300 | G24: =B24*E24+F24 | H24: =G24/C24 | I24: 60500 | J24: 107 | K24: 61220 | N24: 67970 | O24: 66300 | P24: =O24*1.03 | R24: =M24*1.03 | AB24: 57800 | AC24: =AB24*1.03 | AD24: =AB24*1.05
A25: 12,0 мм Ст3 (3000х1500) | B25: 73000 | C25: 4.5 | D25: =E25/C25 | E25: 0.424 | F25: 420 | G25: =B25*E25+F25 | H25: =G25/C25 | I25: 60500 | J25: 128.5 | K25: 61220 | M25: 73000 | O25: 66300 | P25: =O25*1.03 | R25: =M25*1.03 | AB25: 57800 | AC25: =AB25*1.03 | AD25: =AB25*1.05
A26: 16,0 мм Ст3 (3000х1500) | B26: 73000 | C26: 4.5 | D26: =E26/C26 | E26: 0.565 | F26: 710 | G26: =B26*E26+F26 | H26: =G26/C26 | I26: 60500 | J26: 171.5 | K26: 61220 | M26: 70500 | O26: 66300 | P26: =O26*1.03 | R26: =M26*1.03 | AB26: 57800 | AC26: =AB26*1.03 | AD26: =AB26*1.05
A27: 3мм рифл (2500х1250) | B27: 73000 | C27: 3.125 | E27: 0.0756 | G27: =B27*E27+F27 | H27: =G27/C27 | I27: 67400 | O27: 72200 | P27: =O27*1.03 | R27: =M27*1.03 | T27: 72213.02 | W27: =58309*1.22 | X27: =AVERAGE(T27:W27) | Y27: =X27/B27-1 | Z27: =S27/T27-1 | AB27: 72213 | AC27: =AB27*1.03 | AD27: =AB27*1.05
A28: 1мм НЖ (2500х1250) AISI 304 | B28: 320000 | C28: 3.125 | D28: 0.008 | E28: =D28*C28 | G28: =B28*E28+F28 | H28: =G28/C28 | P28: 320000
A29: 1мм НЖ (3000х1500) AISI 304 | B29: 320000 | C29: 4.5 | D29: 0.008 | E29: =D29*C29 | G29: =B29*E29+F29 | H29: =G29/C29 | P29: 320000
A30: Другой материал ( см. примечание) | P30: 320000 | Y30: =AVERAGE(Y8:Y23) | Z30: =AVERAGE(Z8:Z23)
A31: 3мм НЖ (2500х1250) AISI 304 мат | B31: 320000 | C31: 3.125 | E31: 0.075 | G31: =B31*E31+F31 | H31: =G31/C31 | P31: 320000
A32: 2мм НЖ (2500х1250) AISI 304 Шлиф. | B32: 320000 | P32: 320000
A33: 5мм НЖ (2500х1250) AISI 304 | B33: 320000 | P33: 320000
A35: Вид работ | B35: Цена материала
A36: Порошковая покраска | B36: 500
A37: Эмаль покраска | B37: 1350
A38: Грунт + Эмаль покраска | B38: 1350
A39: Грунтовка+ Покраска порошковая | B39: 650

Sheet Лист1
A1: Металл | C1: Покраска | E1: Другое
A2: Марка стали | B2: Листов/ м.кв. для порошковой покраски | C2: Материал покраски/RAL | D2: Использовано, кг. | E2: Материал | F2: Использовано
A3: 1 мм AISI 304
A4: 1 мм Алюминий
A5: 1 мм ОЦ Сталь
A6: 1 мм ХК Сталь
A7: 1,2 мм Алюминий
A8: 1,5 мм ХК Сталь
A9: 1,5 ОЦ Сталь
A10: 1.5 мм ОЦ Сталь
A11: 2 мм AISI 304
A12: 2 мм ОЦ Сталь
A13: 2 мм ХК Сталь
A14: 3 мм ГК Сталь
... A23: 12 мм Сталь 45
